File: MnSi50K
*RAS_DATA_START
*RAS_HEADER_START
*ATMOSPHERE_TEMP_DATAOUT "0.0000000000"
*ATMOSPHERE_TEMP_END "49.9980000000"
*ATMOSPHERE_TEMP_START "50.0010000000"
*ATMOSPHERE_TEMP_UNIT "K"
*ATMOSPHERE_TEMP_UNIT_DISP "1.0000000000"
*DISP_FMT_X "%.3f"
*DISP_FMT_Y "%.0f"
*DISP_FULLSCALE "2227.3771373271"
*DISP_LINE_COLOR "255.0000000000"
*DISP_LINE_STYLE "0.0000000000"
*DISP_LINE_WIDTH "0.2500000000"
*DISP_NOTE "Collected Data-11"
*DISP_OFFSET_Y "0.0000000000"
*DISP_PEAKSEARCH_UNIT_Y "cps"
*DISP_RANGE_BOTTOM "0.0000000000"
*DISP_RANGE_LEFT "30.0000000000"
*DISP_RANGE_LOGCUTOFF "0.0100000000"
*DISP_RANGE_RIGHT "80.0000000000"
*DISP_RANGE_TOP "2227.3771373271"
*DISP_SCALE_MODE_Y "0.0000000000"
*DISP_TAB_NAME "Theta/2-Theta"
*DISP_TITLE_Y "Intensity"
*DISP_UNIT_Y "cps"
*DISP_WINDOW_NAME "MSG_MACROENGINE"
*FILE_COMMENT " "
*FILE_MD5 ""
*FILE_MEMO " "
*FILE_OPERATOR "administrator"
*FILE_PART_ID "MEAS_KHP2_00068"
*FILE_SAMPLE " "
*FILE_TYPE "RAS_RAW"
*FILE_USERGROUP "System Manager"
*FILE_VERSION "1.0000000000"
*HW_ATTACHMENT_ID "ATT0097"
*HW_ATTACHMENT_NAME "極低温アタッチメント(Z)-4K|Ultra-Low Temp. Att.(Z)-4K"
*HW_COUNTER_ID-0 "CUT0021"
*HW_COUNTER_ID-1 "CUT0051"
*HW_COUNTER_ID-2 "CUT0020"
*HW_COUNTER_ID-3 "CSL0021"
*HW_COUNTER_ID-4 "CMC0021"
*HW_COUNTER_NAME-0 "SC-70|SC-70"
*HW_COUNTER_NAME-1 "HyPix 3000(H)|HyPix 3000(H)"
*HW_COUNTER_NAME-2 "None|None"
*HW_COUNTER_NAME-3 "BBM|BBM"
*HW_COUNTER_NAME-4 "検出器モノクロメータ|Detector monochromator"
*HW_COUNTER_SELECT_NAME "HyPix 3000(H)|HyPix 3000(H)"
*HW_GONIOMETER_ID "GON0023"
*HW_GONIOMETER_NAME "SmartLab|SmartLab"
*HW_GONIOMETER_RADIUS-0 "90.0"
*HW_GONIOMETER_RADIUS-1 "114.0"
*HW_GONIOMETER_RADIUS-2 "190.0"
*HW_GONIOMETER_RADIUS-3 "300.0"
*HW_GONIOMETER_RADIUS-4 "187.0"
*HW_GONIOMETER_RADIUS-5 "300.0"
*HW_GONIOMETER_RADIUS-6 "113.0"
*HW_GONIOMETER_RADIUS-7 "331.0"
*HW_I_OPT_ID-0 "CBO0021"
*HW_I_OPT_ID-1 "ICR0023"
*HW_I_OPT_ID-2 "ISL0021"
*HW_I_OPT_ID-3 "ISO0021"
*HW_I_OPT_ID-4 "IAD0021"
*HW_I_OPT_ID-5 "IPR0001"
*HW_I_OPT_NAME-0 "CBOユニット|CBO unit"
*HW_I_OPT_NAME-1 "標準入射光学ユニット|Standard incident optical unit"
*HW_I_OPT_NAME-2 "標準入射スリットボックス|Standard incident slit box"
*HW_I_OPT_NAME-3 "入射平行スリット|Incident parallel slit"
*HW_I_OPT_NAME-4 "長手制限スリット|Length limiting slit"
*HW_I_OPT_NAME-5 "None|None"
*HW_R_ATTENUATER_AUTOMODE "0"
*HW_R_OPT_ID-0 "RSS0022"
*HW_R_OPT_ID-1 "RCR0022"
*HW_R_OPT_ID-2 "RSO0021"
*HW_R_OPT_ID-3 "RRS0022"
*HW_R_OPT_ID-4 "ATN0020"
*HW_R_OPT_ID-5 "RFL0021"
*HW_R_OPT_ID-6 "RAD0021"
*HW_R_OPT_NAME-0 "受光スリットボックス1(Zr軸付)|Receiving slit box # 1 (w/ Zr Axis)"
*HW_R_OPT_NAME-1 "標準受光光学ユニット1|Standard receiving unit # 1"
*HW_R_OPT_NAME-2 "標準受光光学ユニット2|Standard receiving optical unit # 2"
*HW_R_OPT_NAME-3 "仮想受光スリット2|Virtual receiving slit #2"
*HW_R_OPT_NAME-4 "無し|None"
*HW_R_OPT_NAME-5 "Cu Kβ|Cu K-beta"
*HW_R_OPT_NAME-6 "調整用受光スリット|Alignment receiving slit"
*HW_SAMPLE_HOLDER_ID "SMP0020"
*HW_SAMPLE_HOLDER_NAME "無し|None"
*HW_XG_CURRENT_MAX "50"
*HW_XG_CURRENT_MIN "2"
*HW_XG_CURRENT_RESOLUTION "1"
*HW_XG_CURRENT_UNIT "mA"
*HW_XG_FOCUS "0.4mm x 8mm"
*HW_XG_FOCUS_TYPE "Fine"
*HW_XG_ID "1200"
*HW_XG_NAME "3kW 封入管(ID:1200)|3kW Sealed tube(ID:1200)"
*HW_XG_TARGET_ATOMIC_NUMBER "29.0000000000"
*HW_XG_TARGET_NAME "Cu"
*HW_XG_TYPE "Hermetic"
*HW_XG_VOLTAGE_MAX "50"
*HW_XG_VOLTAGE_MIN "20"
*HW_XG_VOLTAGE_RESOLUTION "1"
*HW_XG_VOLTAGE_UNIT "kV"
*HW_XG_WATT_MAX "1.500"
*HW_XG_WATT_UNIT "kW"
*HW_XG_WAVE_LENGTH_ALPHA1 "1.540593"
*HW_XG_WAVE_LENGTH_ALPHA2 "1.544414"
*HW_XG_WAVE_LENGTH_BETA "1.392250"
*MEAS_COND_AXIS_NAME-0 "Theta/2-Theta"
*MEAS_COND_AXIS_NAME-1 "2-Theta"
*MEAS_COND_AXIS_NAME-2 "Omega"
*MEAS_COND_AXIS_NAME-3 "Z"
*MEAS_COND_AXIS_NAME-4 "2-Theta/Omega"
*MEAS_COND_AXIS_NAME-5 "Theta_s"
*MEAS_COND_AXIS_NAME-6 "Theta_d"
*MEAS_COND_AXIS_NAME-7 "Ts"
*MEAS_COND_AXIS_NAME-8 "CBO selection slit"
*MEAS_COND_AXIS_NAME-9 "M"
*MEAS_COND_AXIS_NAME-10 "Incident parallel slit"
*MEAS_COND_AXIS_NAME-11 "Incident slit"
*MEAS_COND_AXIS_NAME-12 ""
*MEAS_COND_AXIS_NAME-13 "Zs"
*MEAS_COND_AXIS_NAME-14 "Incident monochromator"
*MEAS_COND_AXIS_NAME-15 "Length limiting slit"
*MEAS_COND_AXIS_NAME-16 "Center slit"
*MEAS_COND_AXIS_NAME-17 "Filter"
*MEAS_COND_AXIS_NAME-18 "Receiving slit # 1"
*MEAS_COND_AXIS_NAME-19 "Receiving slit # 2"
*MEAS_COND_AXIS_NAME-20 "Receiving optical device"
*MEAS_COND_AXIS_NAME-21 "Receiving parallel slit"
*MEAS_COND_AXIS_NAME-22 "Alignment receiving slit"
*MEAS_COND_AXIS_NAME-23 ""
*MEAS_COND_AXIS_NAME-24 ""
*MEAS_COND_AXIS_NAME-25 "Zd"
*MEAS_COND_AXIS_NAME-26 "Attenuator"
*MEAS_COND_AXIS_NAME-27 "Diffracted beam monochromator"
*MEAS_COND_AXIS_NAME-28 "Monochromator slit"
*MEAS_COND_AXIS_NAME-29 "Zr"
*MEAS_COND_AXIS_NAME-30 "Primary beam"
*MEAS_COND_AXIS_NAME-31 "Temperature"
*MEAS_COND_AXIS_NAME-32 "Temperature2"
*MEAS_COND_AXIS_NAME_INTERNAL-0 "TwoThetaTheta"
*MEAS_COND_AXIS_NAME_INTERNAL-1 "TwoTheta"
*MEAS_COND_AXIS_NAME_INTERNAL-2 "Omega"
*MEAS_COND_AXIS_NAME_INTERNAL-3 "Z"
*MEAS_COND_AXIS_NAME_INTERNAL-4 "TwoThetaOmega"
*MEAS_COND_AXIS_NAME_INTERNAL-5 "ThetaS"
*MEAS_COND_AXIS_NAME_INTERNAL-6 "ThetaD"
*MEAS_COND_AXIS_NAME_INTERNAL-7 "Ts"
*MEAS_COND_AXIS_NAME_INTERNAL-8 "CBO"
*MEAS_COND_AXIS_NAME_INTERNAL-9 "CBO-M"
*MEAS_COND_AXIS_NAME_INTERNAL-10 "IncidentSollerSlit"
*MEAS_COND_AXIS_NAME_INTERNAL-11 "IncidentSlitBox"
*MEAS_COND_AXIS_NAME_INTERNAL-12 "IncidentSlitBox-_Axis"
*MEAS_COND_AXIS_NAME_INTERNAL-13 "Zs"
*MEAS_COND_AXIS_NAME_INTERNAL-14 "IncidentMonochromator"
*MEAS_COND_AXIS_NAME_INTERNAL-15 "IncidentAxdSlit"
*MEAS_COND_AXIS_NAME_INTERNAL-16 "CenterSlit"
*MEAS_COND_AXIS_NAME_INTERNAL-17 "Filter"
*MEAS_COND_AXIS_NAME_INTERNAL-18 "ReceivingSlitBox1"
*MEAS_COND_AXIS_NAME_INTERNAL-19 "ReceivingSlitBox2"
*MEAS_COND_AXIS_NAME_INTERNAL-20 "ReceivingOptics"
*MEAS_COND_AXIS_NAME_INTERNAL-21 "ReceivingSollerSlit"
*MEAS_COND_AXIS_NAME_INTERNAL-22 "ReceivingAxdSlit"
*MEAS_COND_AXIS_NAME_INTERNAL-23 "ReceivingSlitBox1-_Axis"
*MEAS_COND_AXIS_NAME_INTERNAL-24 "ReceivingSlitBox2-_Axis"
*MEAS_COND_AXIS_NAME_INTERNAL-25 "ReceivingSlitBox2-Zd"
*MEAS_COND_AXIS_NAME_INTERNAL-26 "Attenuator"
*MEAS_COND_AXIS_NAME_INTERNAL-27 "CounterMonochromator"
*MEAS_COND_AXIS_NAME_INTERNAL-28 "CounterSlit"
*MEAS_COND_AXIS_NAME_INTERNAL-29 "ReceivingSlitBox1-Zr"
*MEAS_COND_AXIS_NAME_INTERNAL-30 "IncidentPrimary"
*MEAS_COND_AXIS_NAME_INTERNAL-31 "Temperature"
*MEAS_COND_AXIS_NAME_INTERNAL-32 "Temperature2"
*MEAS_COND_AXIS_NAME_MAGICNO-0 "83951616.0000000000"
*MEAS_COND_AXIS_NAME_MAGICNO-1 "268632064.0000000000"
*MEAS_COND_AXIS_NAME_MAGICNO-2 "268500992.0000000000"
*MEAS_COND_AXIS_NAME_MAGICNO-3 "285278208.0000000000"
*MEAS_COND_AXIS_NAME_MAGICNO-4 "83951616.0000000000"
*MEAS_COND_AXIS_NAME_MAGICNO-5 "131072.0000000000"
*MEAS_COND_AXIS_NAME_MAGICNO-6 "131072.0000000000"
*MEAS_COND_AXIS_NAME_MAGICNO-7 "318898176.0000000000"
*MEAS_COND_AXIS_NAME_MAGICNO-8 "20971521.0000000000"
*MEAS_COND_AXIS_NAME_MAGICNO-9 "285343744.0000000000"
*MEAS_COND_AXIS_NAME_MAGICNO-10 "20971521.0000000000"
*MEAS_COND_AXIS_NAME_MAGICNO-11 "22020097.0000000000"
*MEAS_COND_AXIS_NAME_MAGICNO-12 "25165824.0000000000"
*MEAS_COND_AXIS_NAME_MAGICNO-13 "318898176.0000000000"
*MEAS_COND_AXIS_NAME_MAGICNO-14 "1.0000000000"
*MEAS_COND_AXIS_NAME_MAGICNO-15 "20971521.0000000000"
*MEAS_COND_AXIS_NAME_MAGICNO-16 "20971521.0000000000"
*MEAS_COND_AXIS_NAME_MAGICNO-17 "20971521.0000000000"
*MEAS_COND_AXIS_NAME_MAGICNO-18 "23068673.0000000000"
*MEAS_COND_AXIS_NAME_MAGICNO-19 "23068673.0000000000"
*MEAS_COND_AXIS_NAME_MAGICNO-20 "20971521.0000000000"
*MEAS_COND_AXIS_NAME_MAGICNO-21 "20971521.0000000000"
*MEAS_COND_AXIS_NAME_MAGICNO-22 "20971521.0000000000"
*MEAS_COND_AXIS_NAME_MAGICNO-23 "25165824.0000000000"
*MEAS_COND_AXIS_NAME_MAGICNO-24 "25165824.0000000000"
*MEAS_COND_AXIS_NAME_MAGICNO-25 "285343744.0000000000"
*MEAS_COND_AXIS_NAME_MAGICNO-26 "0.0000000000"
*MEAS_COND_AXIS_NAME_MAGICNO-27 "20971521.0000000000"
*MEAS_COND_AXIS_NAME_MAGICNO-28 "20971521.0000000000"
*MEAS_COND_AXIS_NAME_MAGICNO-29 "285343744.0000000000"
*MEAS_COND_AXIS_NAME_MAGICNO-30 "20971521.0000000000"
*MEAS_COND_AXIS_NAME_MAGICNO-31 "0.0000000000"
*MEAS_COND_AXIS_NAME_MAGICNO-32 "0.0000000000"
*MEAS_COND_AXIS_OFFSET-0 "-"
*MEAS_COND_AXIS_OFFSET-1 "0.1390000000"
*MEAS_COND_AXIS_OFFSET-2 "0.0531000000"
*MEAS_COND_AXIS_OFFSET-3 "-"
*MEAS_COND_AXIS_OFFSET-4 "-"
*MEAS_COND_AXIS_OFFSET-5 "0.0531000000"
*MEAS_COND_AXIS_OFFSET-6 "0.0859000000"
*MEAS_COND_AXIS_OFFSET-7 "-"
*MEAS_COND_AXIS_OFFSET-8 "-"
*MEAS_COND_AXIS_OFFSET-9 "-"
*MEAS_COND_AXIS_OFFSET-10 "-"
*MEAS_COND_AXIS_OFFSET-11 "-"
*MEAS_COND_AXIS_OFFSET-12 "-"
*MEAS_COND_AXIS_OFFSET-13 "-"
*MEAS_COND_AXIS_OFFSET-14 "-"
*MEAS_COND_AXIS_OFFSET-15 "-"
*MEAS_COND_AXIS_OFFSET-16 "-"
*MEAS_COND_AXIS_OFFSET-17 "-"
*MEAS_COND_AXIS_OFFSET-18 "-"
*MEAS_COND_AXIS_OFFSET-19 "-"
*MEAS_COND_AXIS_OFFSET-20 "-"
*MEAS_COND_AXIS_OFFSET-21 "-"
*MEAS_COND_AXIS_OFFSET-22 "-"
*MEAS_COND_AXIS_OFFSET-23 "-"
*MEAS_COND_AXIS_OFFSET-24 "-"
*MEAS_COND_AXIS_OFFSET-25 "-"
*MEAS_COND_AXIS_OFFSET-26 "-"
*MEAS_COND_AXIS_OFFSET-27 "-"
*MEAS_COND_AXIS_OFFSET-28 "-"
*MEAS_COND_AXIS_OFFSET-29 "-"
*MEAS_COND_AXIS_OFFSET-30 "-"
*MEAS_COND_AXIS_OFFSET-31 "0.0000000000"
*MEAS_COND_AXIS_OFFSET-32 "0.0000000000"
*MEAS_COND_AXIS_POSITION-0 "0.0000000000"
*MEAS_COND_AXIS_POSITION-1 "0.0000000000"
*MEAS_COND_AXIS_POSITION-2 "0.0000000000"
*MEAS_COND_AXIS_POSITION-3 "0.6204000000"
*MEAS_COND_AXIS_POSITION-4 "0.0000000000"
*MEAS_COND_AXIS_POSITION-5 "0.0000000000"
*MEAS_COND_AXIS_POSITION-6 "0.0000000000"
*MEAS_COND_AXIS_POSITION-7 "-0.5445000000"
*MEAS_COND_AXIS_POSITION-8 "BB"
*MEAS_COND_AXIS_POSITION-9 "0.0000000000"
*MEAS_COND_AXIS_POSITION-10 "Soller_slit_5.0deg"
*MEAS_COND_AXIS_POSITION-11 "1/2deg"
*MEAS_COND_AXIS_POSITION-12 "1.6581000000"
*MEAS_COND_AXIS_POSITION-13 "-0.2778100000"
*MEAS_COND_AXIS_POSITION-14 "0.0000000000"
*MEAS_COND_AXIS_POSITION-15 "15.0mm"
*MEAS_COND_AXIS_POSITION-16 "None"
*MEAS_COND_AXIS_POSITION-17 "Cu_K-beta"
*MEAS_COND_AXIS_POSITION-18 "1/2deg"
*MEAS_COND_AXIS_POSITION-19 "0.300mm"
*MEAS_COND_AXIS_POSITION-20 "PSA_open"
*MEAS_COND_AXIS_POSITION-21 "Soller_slit_5.0deg"
*MEAS_COND_AXIS_POSITION-22 "None"
*MEAS_COND_AXIS_POSITION-23 "0.9862000000"
*MEAS_COND_AXIS_POSITION-24 "0.3000000000"
*MEAS_COND_AXIS_POSITION-25 "0.0000000000"
*MEAS_COND_AXIS_POSITION-26 "-"
*MEAS_COND_AXIS_POSITION-27 "No_unit"
*MEAS_COND_AXIS_POSITION-28 "None"
*MEAS_COND_AXIS_POSITION-29 "0.0650000000"
*MEAS_COND_AXIS_POSITION-30 "None"
*MEAS_COND_AXIS_POSITION-31 "50.0010000000"
*MEAS_COND_AXIS_POSITION-32 "49.9470000000"
*MEAS_COND_AXIS_UNIT-0 "deg"
*MEAS_COND_AXIS_UNIT-1 "deg"
*MEAS_COND_AXIS_UNIT-2 "deg"
*MEAS_COND_AXIS_UNIT-3 "mm"
*MEAS_COND_AXIS_UNIT-4 "deg"
*MEAS_COND_AXIS_UNIT-5 "deg"
*MEAS_COND_AXIS_UNIT-6 "deg"
*MEAS_COND_AXIS_UNIT-7 "mm"
*MEAS_COND_AXIS_UNIT-8 ""
*MEAS_COND_AXIS_UNIT-9 "pulse"
*MEAS_COND_AXIS_UNIT-10 ""
*MEAS_COND_AXIS_UNIT-11 ""
*MEAS_COND_AXIS_UNIT-12 "mm"
*MEAS_COND_AXIS_UNIT-13 "mm"
*MEAS_COND_AXIS_UNIT-14 ""
*MEAS_COND_AXIS_UNIT-15 ""
*MEAS_COND_AXIS_UNIT-16 ""
*MEAS_COND_AXIS_UNIT-17 ""
*MEAS_COND_AXIS_UNIT-18 ""
*MEAS_COND_AXIS_UNIT-19 ""
*MEAS_COND_AXIS_UNIT-20 ""
*MEAS_COND_AXIS_UNIT-21 ""
*MEAS_COND_AXIS_UNIT-22 ""
*MEAS_COND_AXIS_UNIT-23 "mm"
*MEAS_COND_AXIS_UNIT-24 "mm"
*MEAS_COND_AXIS_UNIT-25 "mm"
*MEAS_COND_AXIS_UNIT-26 ""
*MEAS_COND_AXIS_UNIT-27 ""
*MEAS_COND_AXIS_UNIT-28 ""
*MEAS_COND_AXIS_UNIT-29 "mm"
*MEAS_COND_AXIS_UNIT-30 ""
*MEAS_COND_AXIS_UNIT-31 "K"
*MEAS_COND_AXIS_UNIT-32 "K"
*MEAS_COND_COUNTER_CNTLOSS_CORR "0.0000000000"
*MEAS_COND_COUNTER_TAUDIFF "0.0000000000"
*MEAS_COND_COUNTER_TAUINT "0.0000000000"
*MEAS_COND_COUNTER_TEMP_CONDITION "NORMAL"
*MEAS_COND_IRRADIATION_MODE "OFF"
*MEAS_COND_IRRADIATION_WIDTH ""
*MEAS_COND_OPT_ATTR "Bragg-Brentano focusing"
*MEAS_COND_OPT_NAME "@BB focusing"
*MEAS_COND_UNSYMMETRIC_MODE "OFF"
*MEAS_COND_XG_CURRENT "30.0000000000"
*MEAS_COND_XG_VOLTAGE "40.0000000000"
*MEAS_COND_XG_WAVE_TYPE "Ka"
*MEAS_DATA_COUNT "2501.0000000000"
*MEAS_SCAN_AXIS_X "Theta/2-Theta"
*MEAS_SCAN_AXIS_X_INTERNAL "TwoThetaTheta"
*MEAS_SCAN_END_TIME "02/18/20 08:34:28"
*MEAS_SCAN_MODE "CONTINUOUS"
*MEAS_SCAN_MONITOR "0"
*MEAS_SCAN_RESOLUTION_X "0.0002"
*MEAS_SCAN_SPEED "0.301163"
*MEAS_SCAN_SPEED_UNIT "deg/min"
*MEAS_SCAN_SPEED_USER "0.3"
*MEAS_SCAN_START "30.0000000000"
*MEAS_SCAN_START_TIME "02/18/20 05:47:16"
*MEAS_SCAN_STEP "0.0200000000"
*MEAS_SCAN_STOP "80.0000000000"
*MEAS_SCAN_UNIT_X "deg"
*MEAS_SCAN_UNIT_Y "counts"
*RAS_HEADER_END
*RAS_INT_START
30.0000 683.1566 1.0000
30.0400 664.9984 1.0000
30.0800 661.2588 1.0000
30.1200 673.6819 1.0000
30.1600 682.4212 1.0000
30.2000 694.4055 1.0000
30.2400 677.4482 1.0000
30.2800 648.9807 1.0000
30.3200 671.8395 1.0000
30.3600 672.0638 1.0000
30.4000 749.4822 1.0000
30.4400 628.8230 1.0000
30.4800 666.6338 1.0000
30.5200 656.4629 1.0000
30.5600 619.5621 1.0000
30.6000 677.5616 1.0000
30.6400 676.1956 1.0000
30.6800 660.7021 1.0000
30.7200 675.5191 1.0000
30.7600 728.5641 1.0000
30.8000 642.6676 1.0000
30.8400 658.3572 1.0000
30.8800 734.5902 1.0000
30.9200 699.1155 1.0000
30.9600 672.5134 1.0000
31.0000 670.0239 1.0000
31.0400 642.2120 1.0000
31.0800 664.3945 1.0000
31.1200 657.6535 1.0000
31.1600 685.7651 1.0000
31.2000 681.8304 1.0000
31.2400 704.7782 1.0000
31.2800 660.6503 1.0000
31.3200 677.7551 1.0000
31.3600 659.7457 1.0000
31.4000 651.0743 1.0000
31.4400 706.1545 1.0000
31.4800 679.7381 1.0000
31.5200 687.6864 1.0000
31.5600 662.4944 1.0000
31.6000 681.7094 1.0000
31.6400 632.5557 1.0000
31.6800 642.1430 1.0000
31.7200 702.8751 1.0000
31.7600 669.9390 1.0000
31.8000 680.7484 1.0000
31.8400 706.5356 1.0000
31.8800 674.6832 1.0000
31.9200 676.9391 1.0000
31.9600 675.1268 1.0000
32.0000 685.4060 1.0000
32.0400 679.0379 1.0000
32.0800 642.8331 1.0000
32.1200 641.0005 1.0000
32.1600 677.1652 1.0000
32.2000 635.5589 1.0000
32.2400 686.5764 1.0000
32.2800 668.1560 1.0000
32.3200 638.5755 1.0000
32.3600 720.3223 1.0000
32.4000 640.4637 1.0000
32.4400 673.2925 1.0000
32.4800 705.0356 1.0000
32.5200 610.7871 1.0000
32.5600 686.7689 1.0000
32.6000 690.6080 1.0000
32.6400 711.1649 1.0000
32.6800 653.3823 1.0000
32.7200 671.1135 1.0000
32.7600 673.3097 1.0000
32.8000 642.9960 1.0000
32.8400 624.3801 1.0000
32.8800 683.0608 1.0000
32.9200 667.1636 1.0000
32.9600 676.2059 1.0000
33.0000 710.7034 1.0000
33.0400 666.9552 1.0000
33.0800 661.5001 1.0000
33.1200 707.6969 1.0000
33.1600 666.6933 1.0000
33.2000 699.0104 1.0000
33.2400 652.6468 1.0000
33.2800 664.6280 1.0000
33.3200 701.7985 1.0000
33.3600 665.3455 1.0000
33.4000 688.0527 1.0000
33.4400 713.8860 1.0000
33.4800 669.0363 1.0000
33.5200 697.2856 1.0000
33.5600 686.3524 1.0000
33.6000 641.3958 1.0000
33.6400 678.3128 1.0000
33.6800 722.4514 1.0000
33.7200 678.6602 1.0000
33.7600 697.4273 1.0000
33.8000 647.3016 1.0000
33.8400 708.6017 1.0000
33.8800 738.8549 1.0000
33.9200 796.3947 1.0000
33.9600 859.3955 1.0000
34.0000 1109.1281 1.0000
34.0400 1250.8739 1.0000
34.0800 1646.5438 1.0000
34.1200 1798.9500 1.0000
34.1600 1196.5228 1.0000
34.2000 1153.5045 1.0000
34.2400 767.6375 1.0000
34.2800 694.9977 1.0000
34.3200 653.1036 1.0000
34.3600 705.2749 1.0000
34.4000 720.4559 1.0000
34.4400 673.3441 1.0000
34.4800 678.0742 1.0000
34.5200 656.9575 1.0000
34.5600 691.2030 1.0000
34.6000 647.5602 1.0000
34.6400 698.4970 1.0000
34.6800 656.4448 1.0000
34.7200 674.5776 1.0000
34.7600 677.7992 1.0000
34.8000 680.3280 1.0000
34.8400 654.4518 1.0000
34.8800 693.1680 1.0000
34.9200 655.9351 1.0000
34.9600 667.3947 1.0000
35.0000 661.4777 1.0000
35.0400 685.9345 1.0000
35.0800 647.5392 1.0000
35.1200 703.3286 1.0000
35.1600 690.6194 1.0000
35.2000 682.9098 1.0000
35.2400 653.9312 1.0000
35.2800 690.5354 1.0000
35.3200 709.4453 1.0000
35.3600 674.5264 1.0000
35.4000 681.5500 1.0000
35.4400 667.4099 1.0000
35.4800 651.0760 1.0000
35.5200 620.2526 1.0000
35.5600 685.6021 1.0000
35.6000 683.9695 1.0000
35.6400 673.4490 1.0000
35.6800 681.7065 1.0000
35.7200 663.4023 1.0000
35.7600 725.4556 1.0000
35.8000 652.4757 1.0000
35.8400 710.5964 1.0000
35.8800 715.9077 1.0000
35.9200 691.3447 1.0000
35.9600 684.7000 1.0000
36.0000 666.3661 1.0000
36.0400 663.1168 1.0000
36.0800 672.0283 1.0000
36.1200 668.9190 1.0000
36.1600 669.9807 1.0000
36.2000 604.4078 1.0000
36.2400 652.7059 1.0000
36.2800 620.7151 1.0000
36.3200 667.6068 1.0000
36.3600 710.7543 1.0000
36.4000 668.0908 1.0000
36.4400 725.0692 1.0000
36.4800 669.3204 1.0000
36.5200 704.7617 1.0000
36.5600 656.5329 1.0000
36.6000 687.8630 1.0000
36.6400 707.3373 1.0000
36.6800 703.3996 1.0000
36.7200 656.1541 1.0000
36.7600 625.9224 1.0000
36.8000 656.7379 1.0000
36.8400 675.3984 1.0000
36.8800 660.2749 1.0000
36.9200 689.9111 1.0000
36.9600 687.6274 1.0000
37.0000 690.4222 1.0000
37.0400 735.4606 1.0000
37.0800 673.0891 1.0000
37.1200 713.7156 1.0000
37.1600 669.3102 1.0000
37.2000 680.5528 1.0000
37.2400 652.3093 1.0000
37.2800 644.7463 1.0000
37.3200 694.4706 1.0000
37.3600 650.0311 1.0000
37.4000 697.6037 1.0000
37.4400 666.4599 1.0000
37.4800 649.5098 1.0000
37.5200 681.2143 1.0000
37.5600 651.3826 1.0000
37.6000 647.6669 1.0000
37.6400 640.0908 1.0000
37.6800 702.1848 1.0000
37.7200 630.2803 1.0000
37.7600 647.8336 1.0000
37.8000 707.6789 1.0000
37.8400 645.0768 1.0000
37.8800 696.8643 1.0000
37.9200 668.2614 1.0000
37.9600 650.5756 1.0000
38.0000 714.1215 1.0000
38.0400 662.8227 1.0000
38.0800 656.8171 1.0000
38.1200 657.7308 1.0000
38.1600 665.3514 1.0000
38.2000 725.6314 1.0000
38.2400 687.2928 1.0000
38.2800 660.5659 1.0000
38.3200 673.7088 1.0000
38.3600 649.0640 1.0000
38.4000 684.9884 1.0000
38.4400 669.1863 1.0000
38.4800 646.9573 1.0000
38.5200 672.4377 1.0000
38.5600 676.7807 1.0000
38.6000 653.5432 1.0000
38.6400 660.8177 1.0000
38.6800 677.8738 1.0000
38.7200 626.8704 1.0000
38.7600 692.0402 1.0000
38.8000 653.1318 1.0000
38.8400 736.4520 1.0000
38.8800 665.0793 1.0000
38.9200 713.8701 1.0000
38.9600 678.2995 1.0000
39.0000 683.8432 1.0000
39.0400 662.6014 1.0000
39.0800 675.9260 1.0000
39.1200 658.7437 1.0000
39.1600 633.2631 1.0000
39.2000 702.0928 1.0000
39.2400 697.8285 1.0000
39.2800 681.7054 1.0000
39.3200 683.3736 1.0000
39.3600 707.9001 1.0000
39.4000 691.3879 1.0000
39.4400 714.2034 1.0000
39.4800 741.2211 1.0000
39.5200 940.1292 1.0000
39.5600 1196.4628 1.0000
39.6000 1075.5657 1.0000
39.6400 823.8763 1.0000
39.6800 930.9408 1.0000
39.7200 781.9596 1.0000
39.7600 716.9349 1.0000
39.8000 712.4402 1.0000
39.8400 688.4370 1.0000
39.8800 671.9478 1.0000
39.9200 694.9600 1.0000
39.9600 775.9379 1.0000
40.0000 784.6116 1.0000
40.0400 759.8934 1.0000
40.0800 701.2383 1.0000
40.1200 660.5271 1.0000
40.1600 667.1707 1.0000
40.2000 645.2397 1.0000
40.2400 656.8185 1.0000
40.2800 667.5066 1.0000
40.3200 695.6198 1.0000
40.3600 680.9024 1.0000
40.4000 718.4764 1.0000
40.4400 699.7205 1.0000
40.4800 680.6666 1.0000
40.5200 662.0273 1.0000
40.5600 682.3401 1.0000
40.6000 656.9918 1.0000
40.6400 676.4017 1.0000
40.6800 634.9302 1.0000
40.7200 702.1235 1.0000
40.7600 617.1213 1.0000
40.8000 667.0975 1.0000
40.8400 673.3641 1.0000
40.8800 653.6187 1.0000
40.9200 625.2515 1.0000
40.9600 657.4514 1.0000
41.0000 749.0336 1.0000
41.0400 623.7907 1.0000
41.0800 678.5527 1.0000
41.1200 671.7712 1.0000
41.1600 662.1412 1.0000
41.2000 644.4175 1.0000
41.2400 699.4178 1.0000
41.2800 647.9433 1.0000
41.3200 725.1816 1.0000
41.3600 650.6875 1.0000
41.4000 667.0242 1.0000
41.4400 659.5355 1.0000
41.4800 680.4047 1.0000
41.5200 679.2536 1.0000
41.5600 650.9268 1.0000
41.6000 649.2150 1.0000
41.6400 676.4999 1.0000
41.6800 707.8962 1.0000
41.7200 716.1110 1.0000
41.7600 635.4846 1.0000
41.8000 686.8201 1.0000
41.8400 712.9542 1.0000
41.8800 666.3936 1.0000
41.9200 600.4227 1.0000
41.9600 661.3065 1.0000
42.0000 686.7876 1.0000
42.0400 673.7703 1.0000
42.0800 693.4270 1.0000
42.1200 608.6976 1.0000
42.1600 714.9301 1.0000
42.2000 672.1186 1.0000
42.2400 646.4427 1.0000
42.2800 722.8269 1.0000
42.3200 705.2576 1.0000
42.3600 711.1330 1.0000
42.4000 670.6254 1.0000
42.4400 690.5098 1.0000
42.4800 661.4053 1.0000
42.5200 682.3859 1.0000
42.5600 670.6664 1.0000
42.6000 631.5626 1.0000
42.6400 647.9357 1.0000
42.6800 684.6766 1.0000
42.7200 694.7015 1.0000
42.7600 688.0679 1.0000
42.8000 692.5010 1.0000
42.8400 693.8559 1.0000
42.8800 692.4200 1.0000
42.9200 685.4864 1.0000
42.9600 686.6090 1.0000
43.0000 719.7056 1.0000
43.0400 732.0364 1.0000
43.0800 733.9548 1.0000
43.1200 711.4111 1.0000
43.1600 692.1000 1.0000
43.2000 685.7900 1.0000
43.2400 708.7405 1.0000
43.2800 719.3849 1.0000
43.3200 675.4865 1.0000
43.3600 732.6644 1.0000
43.4000 674.1537 1.0000
43.4400 727.1994 1.0000
43.4800 720.3266 1.0000
43.5200 734.6712 1.0000
43.5600 712.4682 1.0000
43.6000 716.6152 1.0000
43.6400 737.6124 1.0000
43.6800 683.3459 1.0000
43.7200 735.4314 1.0000
43.7600 723.1143 1.0000
43.8000 751.5522 1.0000
43.8400 720.7146 1.0000
43.8800 815.2310 1.0000
43.9200 720.4879 1.0000
43.9600 778.1906 1.0000
44.0000 804.7975 1.0000
44.0400 822.3478 1.0000
44.0800 845.2890 1.0000
44.1200 851.4559 1.0000
44.1600 912.9120 1.0000
44.2000 907.1439 1.0000
44.2400 1016.5830 1.0000
44.2800 1095.2432 1.0000
44.3200 1396.1257 1.0000
44.3600 1811.0366 1.0000
44.4000 2844.7944 1.0000
44.4400 5090.6997 1.0000
44.4800 7395.9189 1.0000
44.5200 4084.9707 1.0000
44.5600 3705.1536 1.0000
44.6000 4166.7241 1.0000
44.6400 2041.6697 1.0000
44.6800 1211.4006 1.0000
44.7200 1088.7585 1.0000
44.7600 923.9691 1.0000
44.8000 908.0535 1.0000
44.8400 827.1857 1.0000
44.8800 767.4071 1.0000
44.9200 737.0980 1.0000
44.9600 799.6190 1.0000
45.0000 753.4803 1.0000
45.0400 725.8723 1.0000
45.0800 754.1766 1.0000
45.1200 772.6295 1.0000
45.1600 704.6156 1.0000
45.2000 709.0225 1.0000
45.2400 717.2289 1.0000
45.2800 747.1466 1.0000
45.3200 707.0990 1.0000
45.3600 770.5368 1.0000
45.4000 749.2209 1.0000
45.4400 712.2907 1.0000
45.4800 698.7140 1.0000
45.5200 660.7112 1.0000
45.5600 680.1800 1.0000
45.6000 700.4512 1.0000
45.6400 735.7224 1.0000
45.6800 701.4188 1.0000
45.7200 678.8881 1.0000
45.7600 717.0891 1.0000
45.8000 718.7099 1.0000
45.8400 656.6782 1.0000
45.8800 722.6801 1.0000
45.9200 705.5259 1.0000
45.9600 665.2876 1.0000
46.0000 658.1669 1.0000
46.0400 636.0316 1.0000
46.0800 692.9282 1.0000
46.1200 654.2062 1.0000
46.1600 670.3248 1.0000
46.2000 675.0564 1.0000
46.2400 709.4361 1.0000
46.2800 745.1326 1.0000
46.3200 663.1208 1.0000
46.3600 709.2335 1.0000
46.4000 649.1493 1.0000
46.4400 717.9118 1.0000
46.4800 627.2468 1.0000
46.5200 674.8164 1.0000
46.5600 662.3932 1.0000
46.6000 636.1591 1.0000
46.6400 712.8633 1.0000
46.6800 677.7209 1.0000
46.7200 652.3562 1.0000
46.7600 711.0837 1.0000
46.8000 666.9809 1.0000
46.8400 666.0529 1.0000
46.8800 700.7885 1.0000
46.9200 656.5843 1.0000
46.9600 703.7194 1.0000
47.0000 711.3046 1.0000
47.0400 693.4609 1.0000
47.0800 717.4340 1.0000
47.1200 723.0650 1.0000
47.1600 677.1994 1.0000
47.2000 674.4181 1.0000
47.2400 670.7686 1.0000
47.2800 689.1072 1.0000
47.3200 630.5891 1.0000
47.3600 711.2268 1.0000
47.4000 698.9589 1.0000
47.4400 696.5531 1.0000
47.4800 700.5966 1.0000
47.5200 672.4725 1.0000
47.5600 704.5320 1.0000
47.6000 696.6474 1.0000
47.6400 707.7184 1.0000
47.6800 729.3914 1.0000
47.7200 700.0270 1.0000
47.7600 657.0569 1.0000
47.8000 687.8578 1.0000
47.8400 669.6873 1.0000
47.8800 731.9315 1.0000
47.9200 714.5556 1.0000
47.9600 662.1420 1.0000
48.0000 668.3909 1.0000
48.0400 702.2457 1.0000
48.0800 663.3773 1.0000
48.1200 688.2944 1.0000
48.1600 655.8231 1.0000
48.2000 708.1745 1.0000
48.2400 648.2864 1.0000
48.2800 691.8256 1.0000
48.3200 656.5196 1.0000
48.3600 692.6384 1.0000
48.4000 726.2267 1.0000
48.4400 715.9120 1.0000
48.4800 704.0513 1.0000
48.5200 704.0698 1.0000
48.5600 737.3538 1.0000
48.6000 722.6813 1.0000
48.6400 732.2688 1.0000
48.6800 799.0822 1.0000
48.7200 780.0023 1.0000
48.7600 877.9658 1.0000
48.8000 960.6484 1.0000
48.8400 1064.0546 1.0000
48.8800 1323.2583 1.0000
48.9200 2031.1807 1.0000
48.9600 3132.1733 1.0000
49.0000 4245.0078 1.0000
49.0400 2360.0015 1.0000
49.0800 2010.0592 1.0000
49.1200 2606.9866 1.0000
49.1600 1684.5984 1.0000
49.2000 1056.8604 1.0000
49.2400 878.4440 1.0000
49.2800 865.9102 1.0000
49.3200 768.2661 1.0000
49.3600 761.6307 1.0000
49.4000 767.6917 1.0000
49.4400 738.8365 1.0000
49.4800 691.8644 1.0000
49.5200 746.1723 1.0000
49.5600 701.2103 1.0000
49.6000 749.8967 1.0000
49.6400 691.9341 1.0000
49.6800 690.2358 1.0000
49.7200 689.0540 1.0000
49.7600 692.0012 1.0000
49.8000 757.4218 1.0000
49.8400 711.2859 1.0000
49.8800 642.8159 1.0000
49.9200 690.4528 1.0000
49.9600 699.2805 1.0000
50.0000 730.7877 1.0000
50.0400 696.3867 1.0000
50.0800 634.2758 1.0000
50.1200 685.7577 1.0000
50.1600 723.8641 1.0000
50.2000 676.0493 1.0000
50.2400 706.1794 1.0000
50.2800 706.8550 1.0000
50.3200 671.2690 1.0000
50.3600 683.4113 1.0000
50.4000 662.6479 1.0000
50.4400 686.5608 1.0000
50.4800 660.1888 1.0000
50.5200 711.5576 1.0000
50.5600 672.2424 1.0000
50.6000 687.7164 1.0000
50.6400 666.4573 1.0000
50.6800 691.3275 1.0000
50.7200 667.2197 1.0000
50.7600 693.8618 1.0000
50.8000 694.6641 1.0000
50.8400 708.4289 1.0000
50.8800 673.6069 1.0000
50.9200 700.7985 1.0000
50.9600 690.8457 1.0000
51.0000 677.8385 1.0000
51.0400 743.4512 1.0000
51.0800 674.4401 1.0000
51.1200 701.5055 1.0000
51.1600 690.2217 1.0000
51.2000 685.5288 1.0000
51.2400 693.2510 1.0000
51.2800 662.4403 1.0000
51.3200 691.2500 1.0000
51.3600 705.0578 1.0000
51.4000 687.5274 1.0000
51.4400 687.9148 1.0000
51.4800 654.4288 1.0000
51.5200 703.3453 1.0000
51.5600 694.1367 1.0000
51.6000 663.0234 1.0000
51.6400 663.6616 1.0000
51.6800 699.7010 1.0000
51.7200 699.9128 1.0000
51.7600 673.8906 1.0000
51.8000 730.9515 1.0000
51.8400 634.5189 1.0000
51.8800 707.6226 1.0000
51.9200 667.4709 1.0000
51.9600 630.1998 1.0000
52.0000 665.3413 1.0000
52.0400 718.4404 1.0000
52.0800 669.3204 1.0000
52.1200 662.2227 1.0000
52.1600 699.0123 1.0000
52.2000 666.0295 1.0000
52.2400 653.5856 1.0000
52.2800 633.7691 1.0000
52.3200 626.1932 1.0000
52.3600 673.4580 1.0000
52.4000 694.6512 1.0000
52.4400 690.6638 1.0000
52.4800 655.3958 1.0000
52.5200 688.1389 1.0000
52.5600 682.6411 1.0000
52.6000 691.1173 1.0000
52.6400 690.1786 1.0000
52.6800 709.6227 1.0000
52.7200 706.3449 1.0000
52.7600 689.3096 1.0000
52.8000 675.9618 1.0000
52.8400 705.6817 1.0000
52.8800 688.4333 1.0000
52.9200 674.7135 1.0000
52.9600 657.5624 1.0000
53.0000 665.4785 1.0000
53.0400 700.8458 1.0000
53.0800 663.7808 1.0000
53.1200 671.3773 1.0000
53.1600 621.0711 1.0000
53.2000 670.6934 1.0000
53.2400 682.5135 1.0000
53.2800 694.3486 1.0000
53.3200 709.3948 1.0000
53.3600 728.3636 1.0000
53.4000 679.1313 1.0000
53.4400 656.1422 1.0000
53.4800 658.7197 1.0000
53.5200 682.4227 1.0000
53.5600 700.3516 1.0000
53.6000 682.1655 1.0000
53.6400 698.5951 1.0000
53.6800 680.6802 1.0000
53.7200 691.7434 1.0000
53.7600 675.9103 1.0000
53.8000 621.2381 1.0000
53.8400 719.8350 1.0000
53.8800 637.9197 1.0000
53.9200 715.8113 1.0000
53.9600 657.6858 1.0000
54.0000 685.7912 1.0000
54.0400 637.8495 1.0000
54.0800 688.6676 1.0000
54.1200 659.8247 1.0000
54.1600 698.8834 1.0000
54.2000 665.6336 1.0000
54.2400 672.7727 1.0000
54.2800 696.6176 1.0000
54.3200 660.6757 1.0000
54.3600 659.4357 1.0000
54.4000 658.5906 1.0000
54.4400 651.0035 1.0000
54.4800 699.2472 1.0000
54.5200 667.8292 1.0000
54.5600 672.4773 1.0000
54.6000 649.9946 1.0000
54.6400 732.7604 1.0000
54.6800 675.4866 1.0000
54.7200 672.9581 1.0000
54.7600 693.8608 1.0000
54.8000 638.0318 1.0000
54.8400 688.5101 1.0000
54.8800 715.1002 1.0000
54.9200 662.2863 1.0000
54.9600 677.3780 1.0000
55.0000 654.2128 1.0000
55.0400 660.3575 1.0000
55.0800 615.8250 1.0000
55.1200 665.8362 1.0000
55.1600 644.8433 1.0000
55.2000 653.4029 1.0000
55.2400 654.5877 1.0000
55.2800 666.1445 1.0000
55.3200 631.3862 1.0000
55.3600 671.7636 1.0000
55.4000 667.8389 1.0000
55.4400 672.3864 1.0000
55.4800 655.8971 1.0000
55.5200 663.1000 1.0000
55.5600 669.8486 1.0000
55.6000 677.0886 1.0000
55.6400 699.7518 1.0000
55.6800 684.2490 1.0000
55.7200 683.6340 1.0000
55.7600 657.5917 1.0000
55.8000 664.0723 1.0000
55.8400 679.5448 1.0000
55.8800 665.5689 1.0000
55.9200 689.0882 1.0000
55.9600 666.1704 1.0000
56.0000 688.6817 1.0000
56.0400 728.3641 1.0000
56.0800 656.3318 1.0000
56.1200 727.8393 1.0000
56.1600 655.6873 1.0000
56.2000 711.1321 1.0000
56.2400 649.6656 1.0000
56.2800 701.8692 1.0000
56.3200 704.8843 1.0000
56.3600 690.7177 1.0000
56.4000 640.5271 1.0000
56.4400 691.2589 1.0000
56.4800 712.5834 1.0000
56.5200 681.8483 1.0000
56.5600 698.0472 1.0000
56.6000 675.9948 1.0000
56.6400 604.8933 1.0000
56.6800 685.4084 1.0000
56.7200 675.5264 1.0000
56.7600 672.8636 1.0000
56.8000 692.4318 1.0000
56.8400 686.3772 1.0000
56.8800 723.5259 1.0000
56.9200 692.5435 1.0000
56.9600 695.5869 1.0000
57.0000 669.9904 1.0000
57.0400 677.7808 1.0000
57.0800 690.7745 1.0000
57.1200 664.6311 1.0000
57.1600 680.8825 1.0000
57.2000 724.1848 1.0000
57.2400 728.4658 1.0000
57.2800 681.8674 1.0000
57.3200 712.3955 1.0000
57.3600 688.4187 1.0000
57.4000 685.5743 1.0000
57.4400 679.1267 1.0000
57.4800 635.6152 1.0000
57.5200 700.3657 1.0000
57.5600 681.1259 1.0000
57.6000 704.6575 1.0000
57.6400 692.4896 1.0000
57.6800 658.7311 1.0000
57.7200 684.5989 1.0000
57.7600 683.5032 1.0000
57.8000 625.0516 1.0000
57.8400 666.6662 1.0000
57.8800 752.6002 1.0000
57.9200 695.8569 1.0000
57.9600 687.1172 1.0000
58.0000 701.6754 1.0000
58.0400 635.7719 1.0000
58.0800 633.4170 1.0000
58.1200 674.0858 1.0000
58.1600 671.7296 1.0000
58.2000 678.0806 1.0000
58.2400 656.7858 1.0000
58.2800 694.8832 1.0000
58.3200 728.4887 1.0000
58.3600 697.6868 1.0000
58.4000 694.4854 1.0000
58.4400 671.0833 1.0000
58.4800 698.1252 1.0000
58.5200 651.0894 1.0000
58.5600 741.2868 1.0000
58.6000 712.8458 1.0000
58.6400 724.3892 1.0000
58.6800 721.0071 1.0000
58.7200 695.9219 1.0000
58.7600 676.6313 1.0000
58.8000 669.9847 1.0000
58.8400 658.3202 1.0000
58.8800 732.6425 1.0000
58.9200 732.1137 1.0000
58.9600 670.1771 1.0000
59.0000 660.2247 1.0000
59.0400 681.8079 1.0000
59.0800 648.8493 1.0000
59.1200 679.5126 1.0000
59.1600 662.3506 1.0000
59.2000 649.4384 1.0000
59.2400 693.7074 1.0000
59.2800 675.9203 1.0000
59.3200 657.3696 1.0000
59.3600 698.3423 1.0000
59.4000 652.9052 1.0000
59.4400 714.1977 1.0000
59.4800 703.5681 1.0000
59.5200 706.2033 1.0000
59.5600 646.5028 1.0000
59.6000 658.5646 1.0000
59.6400 662.9833 1.0000
59.6800 683.6392 1.0000
59.7200 672.3505 1.0000
59.7600 681.1079 1.0000
59.8000 709.3013 1.0000
59.8400 666.7145 1.0000
59.8800 682.5394 1.0000
59.9200 671.2369 1.0000
59.9600 671.6179 1.0000
60.0000 677.8290 1.0000
60.0400 661.3541 1.0000
60.0800 700.2100 1.0000
60.1200 688.9063 1.0000
60.1600 662.6290 1.0000
60.2000 688.0591 1.0000
60.2400 670.0802 1.0000
60.2800 653.6883 1.0000
60.3200 679.7360 1.0000
60.3600 724.2530 1.0000
60.4000 639.1016 1.0000
60.4400 633.5204 1.0000
60.4800 693.6055 1.0000
60.5200 683.4507 1.0000
60.5600 681.8325 1.0000
60.6000 706.2020 1.0000
60.6400 716.1080 1.0000
60.6800 697.2878 1.0000
60.7200 691.0555 1.0000
60.7600 714.0505 1.0000
60.8000 667.0275 1.0000
60.8400 642.3665 1.0000
60.8800 746.3703 1.0000
60.9200 689.5177 1.0000
60.9600 844.8237 1.0000
61.0000 842.9106 1.0000
61.0400 994.1559 1.0000
61.0800 818.4157 1.0000
61.1200 790.5897 1.0000
61.1600 779.2227 1.0000
61.2000 838.4738 1.0000
61.2400 838.8785 1.0000
61.2800 738.0039 1.0000
61.3200 742.5573 1.0000
61.3600 684.3636 1.0000
61.4000 674.3130 1.0000
61.4400 661.7788 1.0000
61.4800 740.0652 1.0000
61.5200 658.3585 1.0000
61.5600 711.0242 1.0000
61.6000 683.8659 1.0000
61.6400 694.6550 1.0000
61.6800 684.9203 1.0000
61.7200 664.4437 1.0000
61.7600 664.0977 1.0000
61.8000 712.5878 1.0000
61.8400 720.2598 1.0000
61.8800 655.5168 1.0000
61.9200 664.2780 1.0000
61.9600 669.5560 1.0000
62.0000 654.5612 1.0000
62.0400 631.9876 1.0000
62.0800 682.8248 1.0000
62.1200 695.9852 1.0000
62.1600 700.3966 1.0000
62.2000 699.6047 1.0000
62.2400 692.3773 1.0000
62.2800 715.8659 1.0000
62.3200 699.2177 1.0000
62.3600 649.9650 1.0000
62.4000 692.2271 1.0000
62.4400 650.6353 1.0000
62.4800 682.7202 1.0000
62.5200 680.6793 1.0000
62.5600 682.2415 1.0000
62.6000 672.7536 1.0000
62.6400 682.0109 1.0000
62.6800 702.2120 1.0000
62.7200 679.0958 1.0000
62.7600 691.6515 1.0000
62.8000 684.0287 1.0000
62.8400 663.3100 1.0000
62.8800 691.8697 1.0000
62.9200 649.2127 1.0000
62.9600 675.9632 1.0000
63.0000 673.0666 1.0000
63.0400 681.6271 1.0000
63.0800 667.6610 1.0000
63.1200 692.5355 1.0000
63.1600 684.5189 1.0000
63.2000 665.4700 1.0000
63.2400 683.5886 1.0000
63.2800 673.7725 1.0000
63.3200 710.9122 1.0000
63.3600 697.8566 1.0000
63.4000 685.7292 1.0000
63.4400 689.2016 1.0000
63.4800 660.3950 1.0000
63.5200 608.1716 1.0000
63.5600 649.2376 1.0000
63.6000 647.9477 1.0000
63.6400 713.0396 1.0000
63.6800 696.1917 1.0000
63.7200 648.9500 1.0000
63.7600 689.2666 1.0000
63.8000 696.3542 1.0000
63.8400 670.5565 1.0000
63.8800 691.3891 1.0000
63.9200 649.7139 1.0000
63.9600 661.0984 1.0000
64.0000 687.3842 1.0000
64.0400 710.5911 1.0000
64.0800 665.3316 1.0000
64.1200 664.1190 1.0000
64.1600 674.4810 1.0000
64.2000 690.3577 1.0000
64.2400 636.4047 1.0000
64.2800 671.3896 1.0000
64.3200 701.4423 1.0000
64.3600 686.0703 1.0000
64.4000 623.4581 1.0000
64.4400 661.1034 1.0000
64.4800 662.1390 1.0000
64.5200 665.3981 1.0000
64.5600 743.6277 1.0000
64.6000 729.4702 1.0000
64.6400 759.4075 1.0000
64.6800 774.4141 1.0000
64.7200 877.1545 1.0000
64.7600 936.2467 1.0000
64.8000 774.4219 1.0000
64.8400 710.5257 1.0000
64.8800 755.9790 1.0000
64.9200 887.3971 1.0000
64.9600 743.3875 1.0000
65.0000 682.7869 1.0000
65.0400 668.1445 1.0000
65.0800 679.6850 1.0000
65.1200 673.9561 1.0000
65.1600 684.5170 1.0000
65.2000 683.0588 1.0000
65.2400 658.9122 1.0000
65.2800 683.2999 1.0000
65.3200 661.6268 1.0000
65.3600 672.1168 1.0000
65.4000 640.0880 1.0000
65.4400 716.6035 1.0000
65.4800 672.3798 1.0000
65.5200 629.8610 1.0000
65.5600 654.5168 1.0000
65.6000 688.7928 1.0000
65.6400 686.3606 1.0000
65.6800 645.1379 1.0000
65.7200 642.0836 1.0000
65.7600 700.9755 1.0000
65.8000 711.8029 1.0000
65.8400 665.3660 1.0000
65.8800 647.8002 1.0000
65.9200 672.7420 1.0000
65.9600 631.3995 1.0000
66.0000 651.5133 1.0000
66.0400 696.1146 1.0000
66.0800 651.0683 1.0000
66.1200 719.4305 1.0000
66.1600 701.3770 1.0000
66.2000 724.2354 1.0000
66.2400 664.8423 1.0000
66.2800 682.8721 1.0000
66.3200 695.3432 1.0000
66.3600 679.4349 1.0000
66.4000 653.5516 1.0000
66.4400 665.4456 1.0000
66.4800 676.0165 1.0000
66.5200 701.1873 1.0000
66.5600 732.0973 1.0000
66.6000 707.2861 1.0000
66.6400 681.3016 1.0000
66.6800 699.6869 1.0000
66.7200 706.6948 1.0000
66.7600 705.8518 1.0000
66.8000 699.8259 1.0000
66.8400 708.9260 1.0000
66.8800 687.3527 1.0000
66.9200 711.2073 1.0000
66.9600 672.3801 1.0000
67.0000 690.0945 1.0000
67.0400 685.5793 1.0000
67.0800 692.2366 1.0000
67.1200 633.9367 1.0000
67.1600 675.9302 1.0000
67.2000 680.6935 1.0000
67.2400 679.7358 1.0000
67.2800 647.7527 1.0000
67.3200 663.0443 1.0000
67.3600 677.6805 1.0000
67.4000 651.6899 1.0000
67.4400 706.4771 1.0000
67.4800 699.4731 1.0000
67.5200 704.6860 1.0000
67.5600 657.5668 1.0000
67.6000 683.4134 1.0000
67.6400 691.8745 1.0000
67.6800 687.4890 1.0000
67.7200 672.7252 1.0000
67.7600 693.5671 1.0000
67.8000 715.6108 1.0000
67.8400 714.6405 1.0000
67.8800 675.7550 1.0000
67.9200 748.5281 1.0000
67.9600 661.6711 1.0000
68.0000 734.9345 1.0000
68.0400 711.2296 1.0000
68.0800 737.9432 1.0000
68.1200 729.3748 1.0000
68.1600 766.7385 1.0000
68.2000 838.6729 1.0000
68.2400 942.9590 1.0000
68.2800 1230.0698 1.0000
68.3200 1730.3409 1.0000
68.3600 1334.9917 1.0000
68.4000 986.3672 1.0000
68.4400 946.9705 1.0000
68.4800 1012.3491 1.0000
68.5200 1226.7220 1.0000
68.5600 980.3630 1.0000
68.6000 861.5068 1.0000
68.6400 726.6792 1.0000
68.6800 731.5070 1.0000
68.7200 700.6849 1.0000
68.7600 645.1890 1.0000
68.8000 681.0601 1.0000
68.8400 726.5547 1.0000
68.8800 691.8172 1.0000
68.9200 694.1159 1.0000
68.9600 698.2383 1.0000
69.0000 657.5375 1.0000
69.0400 687.0441 1.0000
69.0800 688.4459 1.0000
69.1200 701.2127 1.0000
69.1600 675.2478 1.0000
69.2000 728.0121 1.0000
69.2400 689.0303 1.0000
69.2800 650.0972 1.0000
69.3200 682.8751 1.0000
69.3600 667.1223 1.0000
69.4000 727.3171 1.0000
69.4400 687.3092 1.0000
69.4800 683.6638 1.0000
69.5200 691.8259 1.0000
69.5600 664.2133 1.0000
69.6000 701.6212 1.0000
69.6400 692.8131 1.0000
69.6800 704.4637 1.0000
69.7200 703.9783 1.0000
69.7600 698.8074 1.0000
69.8000 653.4825 1.0000
69.8400 738.7468 1.0000
69.8800 750.9015 1.0000
69.9200 745.3026 1.0000
69.9600 699.9624 1.0000
70.0000 703.2010 1.0000
70.0400 708.8428 1.0000
70.0800 682.5416 1.0000
70.1200 664.7198 1.0000
70.1600 717.7978 1.0000
70.2000 671.9382 1.0000
70.2400 707.4471 1.0000
70.2800 745.2136 1.0000
70.3200 665.9644 1.0000
70.3600 699.7913 1.0000
70.4000 682.7883 1.0000
70.4400 696.0828 1.0000
70.4800 711.0614 1.0000
70.5200 652.6870 1.0000
70.5600 640.1151 1.0000
70.6000 717.2451 1.0000
70.6400 729.9708 1.0000
70.6800 662.1471 1.0000
70.7200 688.3753 1.0000
70.7600 704.4600 1.0000
70.8000 690.1356 1.0000
70.8400 693.7053 1.0000
70.8800 678.7693 1.0000
70.9200 688.0042 1.0000
70.9600 700.5421 1.0000
71.0000 704.3356 1.0000
71.0400 679.1459 1.0000
71.0800 706.4159 1.0000
71.1200 645.7551 1.0000
71.1600 693.4254 1.0000
71.2000 666.5876 1.0000
71.2400 642.0240 1.0000
71.2800 700.9562 1.0000
71.3200 667.0406 1.0000
71.3600 667.8809 1.0000
71.4000 737.6155 1.0000
71.4400 665.6235 1.0000
71.4800 675.0243 1.0000
71.5200 712.3717 1.0000
71.5600 671.4118 1.0000
71.6000 713.8141 1.0000
71.6400 679.1756 1.0000
71.6800 706.4417 1.0000
71.7200 727.6623 1.0000
71.7600 743.1454 1.0000
71.8000 829.6898 1.0000
71.8400 916.7104 1.0000
71.8800 748.2191 1.0000
71.9200 759.4063 1.0000
71.9600 698.3037 1.0000
72.0000 771.4791 1.0000
72.0400 733.2635 1.0000
72.0800 711.3779 1.0000
72.1200 679.1999 1.0000
72.1600 650.8676 1.0000
72.2000 729.3724 1.0000
72.2400 732.6519 1.0000
72.2800 710.8500 1.0000
72.3200 692.9015 1.0000
72.3600 686.9328 1.0000
72.4000 649.9730 1.0000
72.4400 732.7935 1.0000
72.4800 662.4923 1.0000
72.5200 748.9559 1.0000
72.5600 687.3623 1.0000
72.6000 632.7189 1.0000
72.6400 683.5828 1.0000
72.6800 689.1279 1.0000
72.7200 717.1845 1.0000
72.7600 684.8570 1.0000
72.8000 697.3431 1.0000
72.8400 661.7919 1.0000
72.8800 660.5443 1.0000
72.9200 671.1884 1.0000
72.9600 696.7144 1.0000
73.0000 681.4475 1.0000
73.0400 695.6124 1.0000
73.0800 669.8867 1.0000
73.1200 721.3310 1.0000
73.1600 677.1786 1.0000
73.2000 683.6616 1.0000
73.2400 702.9476 1.0000
73.2800 725.3535 1.0000
73.3200 691.3694 1.0000
73.3600 674.6816 1.0000
73.4000 707.2471 1.0000
73.4400 686.2233 1.0000
73.4800 732.4804 1.0000
73.5200 727.8234 1.0000
73.5600 668.9866 1.0000
73.6000 661.2298 1.0000
73.6400 656.7690 1.0000
73.6800 750.9017 1.0000
73.7200 709.4816 1.0000
73.7600 634.1254 1.0000
73.8000 678.1003 1.0000
73.8400 639.8182 1.0000
73.8800 727.4764 1.0000
73.9200 747.2081 1.0000
73.9600 715.2416 1.0000
74.0000 663.5157 1.0000
74.0400 650.8479 1.0000
74.0800 662.3879 1.0000
74.1200 709.4792 1.0000
74.1600 683.0948 1.0000
74.2000 724.4930 1.0000
74.2400 730.1901 1.0000
74.2800 707.4481 1.0000
74.3200 711.5169 1.0000
74.3600 721.7526 1.0000
74.4000 748.9205 1.0000
74.4400 636.8414 1.0000
74.4800 743.2125 1.0000
74.5200 716.2617 1.0000
74.5600 698.3885 1.0000
74.6000 635.9959 1.0000
74.6400 710.3560 1.0000
74.6800 681.9971 1.0000
74.7200 713.8043 1.0000
74.7600 723.9800 1.0000
74.8000 693.0920 1.0000
74.8400 680.0002 1.0000
74.8800 702.5828 1.0000
74.9200 709.3536 1.0000
74.9600 749.3191 1.0000
75.0000 743.5911 1.0000
75.0400 760.6329 1.0000
75.0800 712.8914 1.0000
75.1200 752.3002 1.0000
75.1600 861.4410 1.0000
75.2000 1019.2306 1.0000
75.2400 1363.3136 1.0000
75.2800 1212.0409 1.0000
75.3200 865.5573 1.0000
75.3600 860.1322 1.0000
75.4000 860.8566 1.0000
75.4400 1011.2401 1.0000
75.4800 1029.0144 1.0000
75.5200 872.5085 1.0000
75.5600 708.1559 1.0000
75.6000 727.0540 1.0000
75.6400 725.3507 1.0000
75.6800 699.0264 1.0000
75.7200 704.2040 1.0000
75.7600 656.7333 1.0000
75.8000 669.6716 1.0000
75.8400 671.3339 1.0000
75.8800 696.6088 1.0000
75.9200 726.4639 1.0000
75.9600 684.1650 1.0000
76.0000 701.7835 1.0000
76.0400 707.7551 1.0000
76.0800 754.4631 1.0000
76.1200 710.9549 1.0000
76.1600 703.5721 1.0000
76.2000 709.0930 1.0000
76.2400 697.6429 1.0000
76.2800 698.0328 1.0000
76.3200 704.5334 1.0000
76.3600 681.3663 1.0000
76.4000 694.3193 1.0000
76.4400 685.0046 1.0000
76.4800 716.8602 1.0000
76.5200 679.0820 1.0000
76.5600 678.9137 1.0000
76.6000 687.2285 1.0000
76.6400 715.0367 1.0000
76.6800 715.2122 1.0000
76.7200 743.8763 1.0000
76.7600 707.0038 1.0000
76.8000 680.3823 1.0000
76.8400 706.2849 1.0000
76.8800 699.5079 1.0000
76.9200 743.9137 1.0000
76.9600 724.6666 1.0000
77.0000 676.7626 1.0000
77.0400 722.4227 1.0000
77.0800 769.7176 1.0000
77.1200 767.3782 1.0000
77.1600 696.7220 1.0000
77.2000 696.6636 1.0000
77.2400 671.3103 1.0000
77.2800 713.6186 1.0000
77.3200 738.5241 1.0000
77.3600 768.7649 1.0000
77.4000 746.3296 1.0000
77.4400 684.0117 1.0000
77.4800 680.8406 1.0000
77.5200 732.2957 1.0000
77.5600 710.3665 1.0000
77.6000 682.1139 1.0000
77.6400 722.6770 1.0000
77.6800 705.0640 1.0000
77.7200 704.4264 1.0000
77.7600 693.9559 1.0000
77.8000 725.3455 1.0000
77.8400 712.3969 1.0000
77.8800 773.6021 1.0000
77.9200 790.1771 1.0000
77.9600 748.3307 1.0000
78.0000 726.0186 1.0000
78.0400 748.4166 1.0000
78.0800 727.3689 1.0000
78.1200 741.6721 1.0000
78.1600 718.5876 1.0000
78.2000 718.4919 1.0000
78.2400 779.2125 1.0000
78.2800 770.9546 1.0000
78.3200 809.6198 1.0000
78.3600 821.5007 1.0000
78.4000 852.8932 1.0000
78.4400 898.2023 1.0000
78.4800 920.4822 1.0000
78.5200 1023.5913 1.0000
78.5600 1475.8502 1.0000
78.6000 2317.2158 1.0000
78.6400 2411.2061 1.0000
78.6800 1627.4326 1.0000
78.7200 1280.8921 1.0000
78.7600 1114.4230 1.0000
78.8000 1299.7029 1.0000
78.8400 1646.8898 1.0000
78.8800 1560.3845 1.0000
78.9200 1154.3745 1.0000
78.9600 948.4129 1.0000
79.0000 891.7907 1.0000
79.0400 798.1985 1.0000
79.0800 747.2391 1.0000
79.1200 770.2412 1.0000
79.1600 728.5853 1.0000
79.2000 761.9303 1.0000
79.2400 739.9655 1.0000
79.2800 742.0896 1.0000
79.3200 726.6494 1.0000
79.3600 738.3679 1.0000
79.4000 729.2348 1.0000
79.4400 696.0334 1.0000
79.4800 725.3876 1.0000
79.5200 703.6324 1.0000
79.5600 734.8538 1.0000
79.6000 667.8448 1.0000
79.6400 725.0698 1.0000
79.6800 732.3714 1.0000
79.7200 716.9524 1.0000
79.7600 704.8796 1.0000
79.8000 725.4393 1.0000
79.8400 707.1168 1.0000
79.8800 680.4213 1.0000
79.9200 730.7233 1.0000
79.9600 750.0118 1.0000
80.0000 634.2408 1.0000
*RAS_INT_END
*RAS_HEADER_START
*ATMOSPHERE_TEMP_DATAOUT "0.0000000000"
*ATMOSPHERE_TEMP_END "50.0000000000"
*ATMOSPHERE_TEMP_START "50.0010000000"
*ATMOSPHERE_TEMP_UNIT "K"
*ATMOSPHERE_TEMP_UNIT_DISP "1.0000000000"
*DISP_FMT_X "%.3f"
*DISP_FMT_Y "%.0f"
*DISP_FULLSCALE "7.3812695138"
*DISP_LINE_COLOR "255.0000000000"
*DISP_LINE_STYLE "0.0000000000"
*DISP_LINE_WIDTH "0.2500000000"
*DISP_NOTE "Collected Data-12"
*DISP_OFFSET_Y "0.0000000000"
*DISP_PEAKSEARCH_UNIT_Y "cps"
*DISP_RANGE_BOTTOM "0.0000000000"
*DISP_RANGE_LEFT "29.0000000000"
*DISP_RANGE_LOGCUTOFF "0.0100000000"
*DISP_RANGE_RIGHT "30.0000000000"
*DISP_RANGE_TOP "7.3812695138"
*DISP_SCALE_MODE_Y "0.0000000000"
*DISP_TAB_NAME "Theta/2-Theta"
*DISP_TITLE_Y "Intensity"
*DISP_UNIT_Y "cps"
*DISP_WINDOW_NAME "MSG_MACROENGINE"
*FILE_COMMENT " "
*FILE_MD5 ""
*FILE_MEMO " "
*FILE_OPERATOR "administrator"
*FILE_PART_ID "MEAS_KHP2_00068"
*FILE_SAMPLE " "
*FILE_TYPE "RAS_RAW"
*FILE_USERGROUP "System Manager"
*FILE_VERSION "1.0000000000"
*HW_ATTACHMENT_ID "ATT0097"
*HW_ATTACHMENT_NAME "極低温アタッチメント(Z)-4K|Ultra-Low Temp. Att.(Z)-4K"
*HW_COUNTER_ID-0 "CUT0021"
*HW_COUNTER_ID-1 "CUT0051"
*HW_COUNTER_ID-2 "CUT0020"
*HW_COUNTER_ID-3 "CSL0021"
*HW_COUNTER_ID-4 "CMC0021"
*HW_COUNTER_NAME-0 "SC-70|SC-70"
*HW_COUNTER_NAME-1 "HyPix 3000(H)|HyPix 3000(H)"
*HW_COUNTER_NAME-2 "None|None"
*HW_COUNTER_NAME-3 "BBM|BBM"
*HW_COUNTER_NAME-4 "検出器モノクロメータ|Detector monochromator"
*HW_COUNTER_SELECT_NAME "HyPix 3000(H)|HyPix 3000(H)"
*HW_GONIOMETER_ID "GON0023"
*HW_GONIOMETER_NAME "SmartLab|SmartLab"
*HW_GONIOMETER_RADIUS-0 "90.0"
*HW_GONIOMETER_RADIUS-1 "114.0"
*HW_GONIOMETER_RADIUS-2 "190.0"
*HW_GONIOMETER_RADIUS-3 "300.0"
*HW_GONIOMETER_RADIUS-4 "187.0"
*HW_GONIOMETER_RADIUS-5 "300.0"
*HW_GONIOMETER_RADIUS-6 "113.0"
*HW_GONIOMETER_RADIUS-7 "331.0"
*HW_I_OPT_ID-0 "CBO0021"
*HW_I_OPT_ID-1 "ICR0023"
*HW_I_OPT_ID-2 "ISL0021"
*HW_I_OPT_ID-3 "ISO0021"
*HW_I_OPT_ID-4 "IAD0021"
*HW_I_OPT_ID-5 "IPR0001"
*HW_I_OPT_NAME-0 "CBOユニット|CBO unit"
*HW_I_OPT_NAME-1 "標準入射光学ユニット|Standard incident optical unit"
*HW_I_OPT_NAME-2 "標準入射スリットボックス|Standard incident slit box"
*HW_I_OPT_NAME-3 "入射平行スリット|Incident parallel slit"
*HW_I_OPT_NAME-4 "長手制限スリット|Length limiting slit"
*HW_I_OPT_NAME-5 "None|None"
*HW_R_ATTENUATER_AUTOMODE "0"
*HW_R_OPT_ID-0 "RSS0022"
*HW_R_OPT_ID-1 "RCR0022"
*HW_R_OPT_ID-2 "RSO0021"
*HW_R_OPT_ID-3 "RRS0022"
*HW_R_OPT_ID-4 "ATN0020"
*HW_R_OPT_ID-5 "RFL0021"
*HW_R_OPT_ID-6 "RAD0021"
*HW_R_OPT_NAME-0 "受光スリットボックス1(Zr軸付)|Receiving slit box # 1 (w/ Zr Axis)"
*HW_R_OPT_NAME-1 "標準受光光学ユニット1|Standard receiving unit # 1"
*HW_R_OPT_NAME-2 "標準受光光学ユニット2|Standard receiving optical unit # 2"
*HW_R_OPT_NAME-3 "仮想受光スリット2|Virtual receiving slit #2"
*HW_R_OPT_NAME-4 "無し|None"
*HW_R_OPT_NAME-5 "Cu Kβ|Cu K-beta"
*HW_R_OPT_NAME-6 "調整用受光スリット|Alignment receiving slit"
*HW_SAMPLE_HOLDER_ID "SMP0020"
*HW_SAMPLE_HOLDER_NAME "無し|None"
*HW_XG_CURRENT_MAX "50"
*HW_XG_CURRENT_MIN "2"
*HW_XG_CURRENT_RESOLUTION "1"
*HW_XG_CURRENT_UNIT "mA"
*HW_XG_FOCUS "0.4mm x 8mm"
*HW_XG_FOCUS_TYPE "Fine"
*HW_XG_ID "1200"
*HW_XG_NAME "3kW 封入管(ID:1200)|3kW Sealed tube(ID:1200)"
*HW_XG_TARGET_ATOMIC_NUMBER "29.0000000000"
*HW_XG_TARGET_NAME "Cu"
*HW_XG_TYPE "Hermetic"
*HW_XG_VOLTAGE_MAX "50"
*HW_XG_VOLTAGE_MIN "20"
*HW_XG_VOLTAGE_RESOLUTION "1"
*HW_XG_VOLTAGE_UNIT "kV"
*HW_XG_WATT_MAX "1.500"
*HW_XG_WATT_UNIT "kW"
*HW_XG_WAVE_LENGTH_ALPHA1 "1.540593"
*HW_XG_WAVE_LENGTH_ALPHA2 "1.544414"
*HW_XG_WAVE_LENGTH_BETA "1.392250"
*MEAS_COND_AXIS_NAME-0 "Theta/2-Theta"
*MEAS_COND_AXIS_NAME-1 "2-Theta"
*MEAS_COND_AXIS_NAME-2 "Omega"
*MEAS_COND_AXIS_NAME-3 "Z"
*MEAS_COND_AXIS_NAME-4 "2-Theta/Omega"
*MEAS_COND_AXIS_NAME-5 "Theta_s"
*MEAS_COND_AXIS_NAME-6 "Theta_d"
*MEAS_COND_AXIS_NAME-7 "Ts"
*MEAS_COND_AXIS_NAME-8 "CBO selection slit"
*MEAS_COND_AXIS_NAME-9 "M"
*MEAS_COND_AXIS_NAME-10 "Incident parallel slit"
*MEAS_COND_AXIS_NAME-11 "Incident slit"
*MEAS_COND_AXIS_NAME-12 ""
*MEAS_COND_AXIS_NAME-13 "Zs"
*MEAS_COND_AXIS_NAME-14 "Incident monochromator"
*MEAS_COND_AXIS_NAME-15 "Length limiting slit"
*MEAS_COND_AXIS_NAME-16 "Center slit"
*MEAS_COND_AXIS_NAME-17 "Filter"
*MEAS_COND_AXIS_NAME-18 "Receiving slit # 1"
*MEAS_COND_AXIS_NAME-19 "Receiving slit # 2"
*MEAS_COND_AXIS_NAME-20 "Receiving optical device"
*MEAS_COND_AXIS_NAME-21 "Receiving parallel slit"
*MEAS_COND_AXIS_NAME-22 "Alignment receiving slit"
*MEAS_COND_AXIS_NAME-23 ""
*MEAS_COND_AXIS_NAME-24 ""
*MEAS_COND_AXIS_NAME-25 "Zd"
*MEAS_COND_AXIS_NAME-26 "Attenuator"
*MEAS_COND_AXIS_NAME-27 "Diffracted beam monochromator"
*MEAS_COND_AXIS_NAME-28 "Monochromator slit"
*MEAS_COND_AXIS_NAME-29 "Zr"
*MEAS_COND_AXIS_NAME-30 "Primary beam"
*MEAS_COND_AXIS_NAME-31 "Temperature"
*MEAS_COND_AXIS_NAME-32 "Temperature2"
*MEAS_COND_AXIS_NAME_INTERNAL-0 "TwoThetaTheta"
*MEAS_COND_AXIS_NAME_INTERNAL-1 "TwoTheta"
*MEAS_COND_AXIS_NAME_INTERNAL-2 "Omega"
*MEAS_COND_AXIS_NAME_INTERNAL-3 "Z"
*MEAS_COND_AXIS_NAME_INTERNAL-4 "TwoThetaOmega"
*MEAS_COND_AXIS_NAME_INTERNAL-5 "ThetaS"
*MEAS_COND_AXIS_NAME_INTERNAL-6 "ThetaD"
*MEAS_COND_AXIS_NAME_INTERNAL-7 "Ts"
*MEAS_COND_AXIS_NAME_INTERNAL-8 "CBO"
*MEAS_COND_AXIS_NAME_INTERNAL-9 "CBO-M"
*MEAS_COND_AXIS_NAME_INTERNAL-10 "IncidentSollerSlit"
*MEAS_COND_AXIS_NAME_INTERNAL-11 "IncidentSlitBox"
*MEAS_COND_AXIS_NAME_INTERNAL-12 "IncidentSlitBox-_Axis"
*MEAS_COND_AXIS_NAME_INTERNAL-13 "Zs"
*MEAS_COND_AXIS_NAME_INTERNAL-14 "IncidentMonochromator"
*MEAS_COND_AXIS_NAME_INTERNAL-15 "IncidentAxdSlit"
*MEAS_COND_AXIS_NAME_INTERNAL-16 "CenterSlit"
*MEAS_COND_AXIS_NAME_INTERNAL-17 "Filter"
*MEAS_COND_AXIS_NAME_INTERNAL-18 "ReceivingSlitBox1"
*MEAS_COND_AXIS_NAME_INTERNAL-19 "ReceivingSlitBox2"
*MEAS_COND_AXIS_NAME_INTERNAL-20 "ReceivingOptics"
*MEAS_COND_AXIS_NAME_INTERNAL-21 "ReceivingSollerSlit"
*MEAS_COND_AXIS_NAME_INTERNAL-22 "ReceivingAxdSlit"
*MEAS_COND_AXIS_NAME_INTERNAL-23 "ReceivingSlitBox1-_Axis"
*MEAS_COND_AXIS_NAME_INTERNAL-24 "ReceivingSlitBox2-_Axis"
*MEAS_COND_AXIS_NAME_INTERNAL-25 "ReceivingSlitBox2-Zd"
*MEAS_COND_AXIS_NAME_INTERNAL-26 "Attenuator"
*MEAS_COND_AXIS_NAME_INTERNAL-27 "CounterMonochromator"
*MEAS_COND_AXIS_NAME_INTERNAL-28 "CounterSlit"
*MEAS_COND_AXIS_NAME_INTERNAL-29 "ReceivingSlitBox1-Zr"
*MEAS_COND_AXIS_NAME_INTERNAL-30 "IncidentPrimary"
*MEAS_COND_AXIS_NAME_INTERNAL-31 "Temperature"
*MEAS_COND_AXIS_NAME_INTERNAL-32 "Temperature2"
*MEAS_COND_AXIS_NAME_MAGICNO-0 "83951616.0000000000"
*MEAS_COND_AXIS_NAME_MAGICNO-1 "268632064.0000000000"
*MEAS_COND_AXIS_NAME_MAGICNO-2 "268500992.0000000000"
*MEAS_COND_AXIS_NAME_MAGICNO-3 "285278208.0000000000"
*MEAS_COND_AXIS_NAME_MAGICNO-4 "83951616.0000000000"
*MEAS_COND_AXIS_NAME_MAGICNO-5 "131072.0000000000"
*MEAS_COND_AXIS_NAME_MAGICNO-6 "131072.0000000000"
*MEAS_COND_AXIS_NAME_MAGICNO-7 "318898176.0000000000"
*MEAS_COND_AXIS_NAME_MAGICNO-8 "20971521.0000000000"
*MEAS_COND_AXIS_NAME_MAGICNO-9 "285343744.0000000000"
*MEAS_COND_AXIS_NAME_MAGICNO-10 "20971521.0000000000"
*MEAS_COND_AXIS_NAME_MAGICNO-11 "22020097.0000000000"
*MEAS_COND_AXIS_NAME_MAGICNO-12 "25165824.0000000000"
*MEAS_COND_AXIS_NAME_MAGICNO-13 "318898176.0000000000"
*MEAS_COND_AXIS_NAME_MAGICNO-14 "1.0000000000"
*MEAS_COND_AXIS_NAME_MAGICNO-15 "20971521.0000000000"
*MEAS_COND_AXIS_NAME_MAGICNO-16 "20971521.0000000000"
*MEAS_COND_AXIS_NAME_MAGICNO-17 "20971521.0000000000"
*MEAS_COND_AXIS_NAME_MAGICNO-18 "23068673.0000000000"
*MEAS_COND_AXIS_NAME_MAGICNO-19 "23068673.0000000000"
*MEAS_COND_AXIS_NAME_MAGICNO-20 "20971521.0000000000"
*MEAS_COND_AXIS_NAME_MAGICNO-21 "20971521.0000000000"
*MEAS_COND_AXIS_NAME_MAGICNO-22 "20971521.0000000000"
*MEAS_COND_AXIS_NAME_MAGICNO-23 "25165824.0000000000"
*MEAS_COND_AXIS_NAME_MAGICNO-24 "25165824.0000000000"
*MEAS_COND_AXIS_NAME_MAGICNO-25 "285343744.0000000000"
*MEAS_COND_AXIS_NAME_MAGICNO-26 "0.0000000000"
*MEAS_COND_AXIS_NAME_MAGICNO-27 "20971521.0000000000"
*MEAS_COND_AXIS_NAME_MAGICNO-28 "20971521.0000000000"
*MEAS_COND_AXIS_NAME_MAGICNO-29 "285343744.0000000000"
*MEAS_COND_AXIS_NAME_MAGICNO-30 "20971521.0000000000"
*MEAS_COND_AXIS_NAME_MAGICNO-31 "0.0000000000"
*MEAS_COND_AXIS_NAME_MAGICNO-32 "0.0000000000"
*MEAS_COND_AXIS_OFFSET-0 "-"
*MEAS_COND_AXIS_OFFSET-1 "0.1390000000"
*MEAS_COND_AXIS_OFFSET-2 "0.0531000000"
*MEAS_COND_AXIS_OFFSET-3 "-"
*MEAS_COND_AXIS_OFFSET-4 "-"
*MEAS_COND_AXIS_OFFSET-5 "0.0531000000"
*MEAS_COND_AXIS_OFFSET-6 "0.0859000000"
*MEAS_COND_AXIS_OFFSET-7 "-"
*MEAS_COND_AXIS_OFFSET-8 "-"
*MEAS_COND_AXIS_OFFSET-9 "-"
*MEAS_COND_AXIS_OFFSET-10 "-"
*MEAS_COND_AXIS_OFFSET-11 "-"
*MEAS_COND_AXIS_OFFSET-12 "-"
*MEAS_COND_AXIS_OFFSET-13 "-"
*MEAS_COND_AXIS_OFFSET-14 "-"
*MEAS_COND_AXIS_OFFSET-15 "-"
*MEAS_COND_AXIS_OFFSET-16 "-"
*MEAS_COND_AXIS_OFFSET-17 "-"
*MEAS_COND_AXIS_OFFSET-18 "-"
*MEAS_COND_AXIS_OFFSET-19 "-"
*MEAS_COND_AXIS_OFFSET-20 "-"
*MEAS_COND_AXIS_OFFSET-21 "-"
*MEAS_COND_AXIS_OFFSET-22 "-"
*MEAS_COND_AXIS_OFFSET-23 "-"
*MEAS_COND_AXIS_OFFSET-24 "-"
*MEAS_COND_AXIS_OFFSET-25 "-"
*MEAS_COND_AXIS_OFFSET-26 "-"
*MEAS_COND_AXIS_OFFSET-27 "-"
*MEAS_COND_AXIS_OFFSET-28 "-"
*MEAS_COND_AXIS_OFFSET-29 "-"
*MEAS_COND_AXIS_OFFSET-30 "-"
*MEAS_COND_AXIS_OFFSET-31 "0.0000000000"
*MEAS_COND_AXIS_OFFSET-32 "0.0000000000"
*MEAS_COND_AXIS_POSITION-0 "80.0474000000"
*MEAS_COND_AXIS_POSITION-1 "80.0474000000"
*MEAS_COND_AXIS_POSITION-2 "40.0237000000"
*MEAS_COND_AXIS_POSITION-3 "0.6204000000"
*MEAS_COND_AXIS_POSITION-4 "80.0474000000"
*MEAS_COND_AXIS_POSITION-5 "40.0237000000"
*MEAS_COND_AXIS_POSITION-6 "40.0237000000"
*MEAS_COND_AXIS_POSITION-7 "-0.5445000000"
*MEAS_COND_AXIS_POSITION-8 "BB"
*MEAS_COND_AXIS_POSITION-9 "0.0000000000"
*MEAS_COND_AXIS_POSITION-10 "Soller_slit_5.0deg"
*MEAS_COND_AXIS_POSITION-11 "1/2deg"
*MEAS_COND_AXIS_POSITION-12 "1.6581000000"
*MEAS_COND_AXIS_POSITION-13 "-0.2778100000"
*MEAS_COND_AXIS_POSITION-14 "0.0000000000"
*MEAS_COND_AXIS_POSITION-15 "15.0mm"
*MEAS_COND_AXIS_POSITION-16 "None"
*MEAS_COND_AXIS_POSITION-17 "Cu_K-beta"
*MEAS_COND_AXIS_POSITION-18 "1/2deg"
*MEAS_COND_AXIS_POSITION-19 "0.300mm"
*MEAS_COND_AXIS_POSITION-20 "PSA_open"
*MEAS_COND_AXIS_POSITION-21 "Soller_slit_5.0deg"
*MEAS_COND_AXIS_POSITION-22 "None"
*MEAS_COND_AXIS_POSITION-23 "0.9862000000"
*MEAS_COND_AXIS_POSITION-24 "0.3000000000"
*MEAS_COND_AXIS_POSITION-25 "0.0000000000"
*MEAS_COND_AXIS_POSITION-26 "-"
*MEAS_COND_AXIS_POSITION-27 "No_unit"
*MEAS_COND_AXIS_POSITION-28 "None"
*MEAS_COND_AXIS_POSITION-29 "0.0650000000"
*MEAS_COND_AXIS_POSITION-30 "None"
*MEAS_COND_AXIS_POSITION-31 "50.0010000000"
*MEAS_COND_AXIS_POSITION-32 "49.9490000000"
*MEAS_COND_AXIS_UNIT-0 "deg"
*MEAS_COND_AXIS_UNIT-1 "deg"
*MEAS_COND_AXIS_UNIT-2 "deg"
*MEAS_COND_AXIS_UNIT-3 "mm"
*MEAS_COND_AXIS_UNIT-4 "deg"
*MEAS_COND_AXIS_UNIT-5 "deg"
*MEAS_COND_AXIS_UNIT-6 "deg"
*MEAS_COND_AXIS_UNIT-7 "mm"
*MEAS_COND_AXIS_UNIT-8 ""
*MEAS_COND_AXIS_UNIT-9 "pulse"
*MEAS_COND_AXIS_UNIT-10 ""
*MEAS_COND_AXIS_UNIT-11 ""
*MEAS_COND_AXIS_UNIT-12 "mm"
*MEAS_COND_AXIS_UNIT-13 "mm"
*MEAS_COND_AXIS_UNIT-14 ""
*MEAS_COND_AXIS_UNIT-15 ""
*MEAS_COND_AXIS_UNIT-16 ""
*MEAS_COND_AXIS_UNIT-17 ""
*MEAS_COND_AXIS_UNIT-18 ""
*MEAS_COND_AXIS_UNIT-19 ""
*MEAS_COND_AXIS_UNIT-20 ""
*MEAS_COND_AXIS_UNIT-21 ""
*MEAS_COND_AXIS_UNIT-22 ""
*MEAS_COND_AXIS_UNIT-23 "mm"
*MEAS_COND_AXIS_UNIT-24 "mm"
*MEAS_COND_AXIS_UNIT-25 "mm"
*MEAS_COND_AXIS_UNIT-26 ""
*MEAS_COND_AXIS_UNIT-27 ""
*MEAS_COND_AXIS_UNIT-28 ""
*MEAS_COND_AXIS_UNIT-29 "mm"
*MEAS_COND_AXIS_UNIT-30 ""
*MEAS_COND_AXIS_UNIT-31 "K"
*MEAS_COND_AXIS_UNIT-32 "K"
*MEAS_COND_COUNTER_CNTLOSS_CORR "0.0000000000"
*MEAS_COND_COUNTER_TAUDIFF "0.0000000000"
*MEAS_COND_COUNTER_TAUINT "0.0000000000"
*MEAS_COND_COUNTER_TEMP_CONDITION "NORMAL"
*MEAS_COND_IRRADIATION_MODE "OFF"
*MEAS_COND_IRRADIATION_WIDTH ""
*MEAS_COND_OPT_ATTR "Bragg-Brentano focusing"
*MEAS_COND_OPT_NAME "@BB focusing"
*MEAS_COND_UNSYMMETRIC_MODE "OFF"
*MEAS_COND_XG_CURRENT "2.0000000000"
*MEAS_COND_XG_VOLTAGE "20.0000000000"
*MEAS_COND_XG_WAVE_TYPE "Ka"
*MEAS_DATA_COUNT "6.0000000000"
*MEAS_SCAN_AXIS_X "Theta/2-Theta"
*MEAS_SCAN_AXIS_X_INTERNAL "TwoThetaTheta"
*MEAS_SCAN_END_TIME "02/18/20 08:35:15"
*MEAS_SCAN_MODE "CONTINUOUS"
*MEAS_SCAN_MONITOR "0"
*MEAS_SCAN_RESOLUTION_X "0.0002"
*MEAS_SCAN_SPEED "73.732692"
*MEAS_SCAN_SPEED_UNIT "deg/min"
*MEAS_SCAN_SPEED_USER "50.0"
*MEAS_SCAN_START "29.0000000000"
*MEAS_SCAN_START_TIME "02/18/20 08:34:46"
*MEAS_SCAN_STEP "0.2000000000"
*MEAS_SCAN_STOP "30.0000000000"
*MEAS_SCAN_UNIT_X "deg"
*MEAS_SCAN_UNIT_Y "counts"
*RAS_HEADER_END
*RAS_INT_START
29.0000 0.0000 1.0000
29.2000 0.0000 1.0000
29.4000 1.0011 1.0000
29.6000 0.0000 1.0000
29.8000 0.7523 1.0000
30.0000 0.2538 1.0000
*RAS_INT_END
*RAS_DATA_END